# 错误处理

## 目录

-   [分类](#分类)
-   [panic](#panic)
-   [.unwrap()](#unwrap)
-   [向上传播：?](#向上传播)

# 分类

-   可恢复错误

    说明：通常用于从系统全局角度来看可以接受的错误，些错误只会影响某个用户自身的操作进程，而不会对系统的全局稳定性产生影响

    示例：处理用户的访问、操作等错误

    代码：`Result<T,E>`
-   不可恢复错误

    说明：该错误通常是全局性或者系统性的错误

    示例：数组越界访问，系统启动时发生了影响启动流程的错误

    代码：`panic!()`

# panic

-   终止方式
    -   栈展开（默认）
    -   直接终止

        修改 `Cargo.toml` 文件，实现在 [release](https://course.rs/first-try/cargo.html#手动编译和运行项目 "release") 模式下遇到 `panic` 直接终止：
        ```ini
        [profile.release]
        panic = 'abort'
        ```
-   原理
    -   情况一（常见）

        当调用 `panic!` 宏时，它会
        1.  格式化 `panic` 信息，然后使用该信息作为参数，调用 `std::panic::panic_any()` 函数
        2.  `panic_any` 会检查应用是否使用了 [panic hook](https://doc.rust-lang.org/std/panic/fn.set_hook.html "panic hook")，如果使用了，该 `hook` 函数就会被调用（`hook` 是一个钩子函数，是外部代码设置的，用于在 `panic` 触发时，执行外部代码所需的功能）
        3.  当 `hook` 函数返回后，当前的线程就开始进行栈展开：从 `panic_any` 开始，如果寄存器或者栈因为某些原因信息错乱了，那很可能该展开会发生异常，最终线程会直接停止，展开也无法继续进行
        4.  展开的过程是一帧一帧的去回溯整个栈，每个帧的数据都会随之被丢弃，但是在展开过程中，你可能会遇到被用户标记为 `catching` 的帧（通过 `std::panic::catch_unwind()` 函数标记），此时用户提供的 `catch` 函数会被调用，展开也随之停止：当然，如果 `catch` 选择在内部调用 `std::panic::resume_unwind()` 函数，则展开还会继续。
    -   情况二

        展开过程中，如果展开本身 `panic` 了，那展开线程会终止，展开也随之停止。
        一旦线程展开被终止或者完成，最终的输出结果是取决于哪个线程 `panic`：对于 `main` 线程，操作系统提供的终止功能 `core::intrinsics::abort()` 会被调用，最终结束当前的 `panic` 进程；如果是其它子线程，那么子线程就会简单的终止，同时信息会在稍后通过 `std::thread::join()` 进行收集。

# .unwrap()

说明：`unwrap()` 是一种方法用于处理 `Option` 和 `Result` 类型的值。它是一个用于提取 `Option` 或 `Result` 的值的简便方法，如果值是 `Some` 或 `Ok`，则返回内部的值；如果是 `None` 或 `Err`，则会引发 panic。

# 向上传播：`?`

-   使用方法
    -   `let v = xxx()?;`
    -   `xxx()?.yyy()?;`
-   示例
    -   用于`Result<T,E>`
        ```rust
        use std::fs::File;
        use std::io;
        use std::io::Read;

        fn read_username_from_file() -> Result<String, io::Error> {
            let mut f = File::open("hello.txt")?;
            let mut s = String::new();
            
            // let mut f = match f {
            //  打开文件成功，将file句柄赋值给f
            // Ok(file) => file,
            //  打开文件失败，将错误返回(向上传播)
            // Err(e) => return Err(e),
            // };
            // 等同于
            f.read_to_string(&mut s)?;
            


            Ok(s)
        }

        ```
    -   用于`Option`
        ```rust
        fn divide(a: f64, b: f64) -> Option<f64> {
            if b == 0.0 {
                None
            } else {
                Some(a / b)
            }
        }

        fn main() -> Result<(), String> {
            let result = divide(10.0, 2.0)?;
            println!("Result: {}", result);

            let result = divide(10.0, 0.0)?;
            println!("Result: {}", result); // 这行不会执行

            // Ok(()) 只是一个惯用的写法，表示成功的结果，而不包含任何有用的值。
            // 表示 main 函数成功地执行并返回一个不包含任何有用信息的成功值。() 是一个表示空元组的值。
            Ok(())
        }
        ```
-   意义

    这种转换非常好用，意味着你可以用一个大而全的 `ReturnError` 来覆盖所有错误类型，只需要为各种子错误类型实现这种转换即可。
-   本质

    根本原因是在于标准库中定义的 `From` 特征，该特征有一个方法 `from`，用于把一个类型转成另外一个类型，`?` 可以自动调用该方法，然后进行隐式类型转换。因此只要函数返回的错误 `ReturnError` 实现了 `From<OtherError>` 特征，那么 `?` 就会自动把 `OtherError` 转换为 `ReturnError`
